{"uuid":"d5c1b489-18af-4b79-8c08-77c05388cb61","historyId":"e24a07d290162b25c3f3d007544d9981","fullName":"com.thetestingacademy.tests.PageObjectModeltest.vwo.TestVWOLogin_03_Retry.testFail","labels":[{"name":"package","value":"com.thetestingacademy.tests.PageObjectModeltest.vwo.TestVWOLogin_03_Retry"},{"name":"testClass","value":"com.thetestingacademy.tests.PageObjectModeltest.vwo.TestVWOLogin_03_Retry"},{"name":"testMethod","value":"testFail"},{"name":"parentSuite","value":"All Test Suite"},{"name":"suite","value":"ATB12xSeleniumAdvanceFramework"},{"name":"subSuite","value":"com.thetestingacademy.tests.PageObjectModeltest.vwo.TestVWOLogin_03_Retry"},{"name":"host","value":"PZPTTECHLT48"},{"name":"thread","value":"5608@PZPTTECHLT48.main(3)"},{"name":"framework","value":"testng"},{"name":"language","value":"java"},{"name":"owner","value":"Akash"}],"links":[],"name":"testFail","status":"skipped","statusDetails":{"known":false,"muted":false,"flaky":false,"message":"expected [true] but found [false]","trace":"java.lang.AssertionError: expected [true] but found [false]\r\n\tat org.testng.Assert.fail(Assert.java:111)\r\n\tat org.testng.Assert.failNotEquals(Assert.java:1590)\r\n\tat org.testng.Assert.assertTrue(Assert.java:57)\r\n\tat org.testng.Assert.assertTrue(Assert.java:67)\r\n\tat com.thetestingacademy.tests.PageObjectModeltest.vwo.TestVWOLogin_03_Retry.testFail(TestVWOLogin_03_Retry.java:30)\r\n\tat java.base/jdk.internal.reflect.DirectMethodHandleAccessor.invoke(DirectMethodHandleAccessor.java:104)\r\n\tat java.base/java.lang.reflect.Method.invoke(Method.java:565)\r\n\tat org.testng.internal.invokers.MethodInvocationHelper.invokeMethod(MethodInvocationHelper.java:141)\r\n\tat org.testng.internal.invokers.TestInvoker.invokeMethod(TestInvoker.java:687)\r\n\tat org.testng.internal.invokers.TestInvoker.retryFailed(TestInvoker.java:269)\r\n\tat org.testng.internal.invokers.MethodRunner.runInSequence(MethodRunner.java:76)\r\n\tat org.testng.internal.invokers.TestInvoker$MethodInvocationAgent.invoke(TestInvoker.java:995)\r\n\tat org.testng.internal.invokers.TestInvoker.invokeTestMethods(TestInvoker.java:203)\r\n\tat org.testng.internal.invokers.TestMethodWorker.invokeTestMethods(TestMethodWorker.java:154)\r\n\tat org.testng.internal.invokers.TestMethodWorker.run(TestMethodWorker.java:134)\r\n\tat java.base/java.util.ArrayList.forEach(ArrayList.java:1604)\r\n\tat org.testng.TestRunner.privateRun(TestRunner.java:741)\r\n\tat org.testng.TestRunner.run(TestRunner.java:616)\r\n\tat org.testng.SuiteRunner.runTest(SuiteRunner.java:421)\r\n\tat org.testng.SuiteRunner.runSequentially(SuiteRunner.java:413)\r\n\tat org.testng.SuiteRunner.privateRun(SuiteRunner.java:373)\r\n\tat org.testng.SuiteRunner.run(SuiteRunner.java:312)\r\n\tat org.testng.SuiteRunnerWorker.runSuite(SuiteRunnerWorker.java:52)\r\n\tat org.testng.SuiteRunnerWorker.run(SuiteRunnerWorker.java:95)\r\n\tat org.testng.TestNG.runSuitesSequentially(TestNG.java:1274)\r\n\tat org.testng.TestNG.runSuitesLocally(TestNG.java:1208)\r\n\tat org.testng.TestNG.runSuites(TestNG.java:1112)\r\n\tat org.testng.TestNG.run(TestNG.java:1079)\r\n\tat com.intellij.rt.testng.IDEARemoteTestNG.run(IDEARemoteTestNG.java:65)\r\n\tat com.intellij.rt.testng.RemoteTestNGStarter.main(RemoteTestNGStarter.java:105)\r\n"},"stage":"finished","description":"Verify that invalid creds give error message","steps":[],"attachments":[{"name":"Log output","source":"f95e41c2-7d86-4c32-86df-56ca7143c403-attachment.txt","type":"text/plain"}],"parameters":[],"start":1756707940098,"stop":1756707945230}